Workbook

Sheet Table
A1: Medicaid Managed Care Enrollment and Spending
C2: Total Medicaid Managed Care Enrollment | F2: Growth Trends | H2: State Spending | K2: Per Capita Spending
A3: State Fiscal Year | B3: Months Reported | C3: Enrollee Months | D3: Average Annual Enrollment | E3: End of Period Enrollment | F3: Enrollee Months Annual Change | G3: Enrollee Months % Growth | H3: State Spending (Millions) | I3: State Spending Annual Change (Millions) | J3: State Spending Annual Change % | K3: Average Annual Spending per Enrollee | L3: Average Annual Spending per Enrollee Annual Change | M3: Average Annual Per Capita Spending % Growth
A4: FY30 (Forecast) | C4: =D4*12 -> 57965641 | D4: =(1+$G$28)*D5 -> 4830470.1 | E4: NA | F4: =C4-C5 -> 1030525.6 | G4: =F4/C5 -> 0.0181 | H4: =K4*D4 -> 2.307236e+10 | I4: =H4-H5 -> 7.296856e+08 | J4: =I4/H5 -> 0.03265883 | K4: =(1+M4)*K5 -> 4776.4212 | L4: =K4-K5 -> 67.339864 | M4: =$G$30 -> 0.0143
A5: FY29 (Forecast) | C5: =D5*12 -> 56935116 | D5: =(1+$G$28)*D6 -> 4744593 | E5: NA | F5: =C5-C6 -> 1012204.7 | G5: =F5/C6 -> 0.0181 | H5: =K5*D5 -> 2.2342674e+10 | I5: =H5-H6 -> 7.0660859e+08 | J5: =I5/H6 -> 0.03265883 | K5: =(1+M5)*K6 -> 4709.0814 | L5: =K5-K6 -> 66.39048 | M5: =$G$30 -> 0.0143
A6: FY28 (Forecast) | C6: =D6*12 -> 55922911 | D6: =(1+$G$28)*D7 -> 4660242.6 | E6: NA | F6: =C6-C7 -> 994209.49 | G6: =F6/C7 -> 0.0181 | H6: =K6*D6 -> 2.1636066e+10 | I6: =H6-H7 -> 6.8426142e+08 | J6: =I6/H7 -> 0.03265883 | K6: =(1+M6)*K7 -> 4642.6909 | L6: =K6-K7 -> 65.454481 | M6: =$G$30 -> 0.0143
A7: FY27 (Forecast) | C7: =D7*12 -> 54928701 | D7: =(1+$G$28)*D8 -> 4577391.8 | E7: NA | F7: =C7-C8 -> 1680126.1 | G7: =G28 -> 0.0181 | H7: =K7*D7 -> 2.0951804e+10 | I7: =H7-H8 -> 6.6262099e+08 | J7: =I7/H8 -> 0.03265883 | K7: =(1+M7)*K8 -> 4577.2364 | L7: =K7-K8 -> 64.531678 | M7: =$G$30 -> 0.0143
A8: FY26 (Estimate)(1)(2) | C8: =C9/(B9/12) -> 53248575 | D8: =((C8+C10)/2)/12 -> 4496013.9 | E8: =C8/12 -> 4437381.3 | F8: =C8-C10 -> -1407183.7 | G8: =(C8-C10)/C10 -> -0.025746303 | H8: =K8*D8 -> 2.0289183e+10 | I8: =H8-H10 -> 25183339 | J8: =I8/H10 -> 0.0012427625 | K8: =(1+M8)*K10 -> 4512.7047 | L8: =K8-K10 -> 63.621885 | M8: =$G$30 -> 0.0143
A9: FY26 (YTD) | B9: 11 | C9: 48811194 | D9: 4437381.3 | E9: 4442646 | F9: NA | G9: NA | H9: NA | I9: NA | J9: NA | K9: NA | L9: NA | M9: NA
A10: FY25 | B10: 12 | C10: 54655759 | D10: 4554646.6 | E10: 4480486 | F10: -8855242 | G10: -0.13942847 | H10: 20264000000 | I10: -1749000000 | J10: -0.07945305 | K10: 4449.0828 | L10: 289.8664 | M10: 0.06969255
A11: FY24 | B11: 12 | C11: 63511001 | D11: 5292583.4 | E11: 5080545 | F11: -1742150 | G11: -0.026698328 | H11: 22013000000 | I11: 909000000 | J11: 0.043072403 | K11: 4159.2164 | L11: 278.20846 | M11: 0.07168459
A12: FY23 | B12: 12 | C12: 65253151 | D12: 5437762.6 | E12: 5494358 | F12: 2794207 | G12: 0.044736699 | H12: 21104000000 | I12: 1470000000 | J12: 0.074870123 | K12: 3881.008 | L12: 108.80204 | M12: 0.02884308
A13: FY22 | B13: 12 | C13: 62458944 | D13: 5204912 | E13: 5252419 | F13: 5547527 | G13: 0.097476522 | H13: 19634000000 | I13: 1948000000 | J13: 0.11014362 | K13: 3772.2059 | L13: 43.042078 | M13: 0.011542018
A14: FY21 | B14: 12 | C14: 56911417 | D14: 4742618.1 | E14: 4947832 | F14: 5853421 | G14: 0.11464259 | H14: 17686000000 | I14: -152000000 | J14: -0.0085211347 | K14: 3729.1639 | L14: -463.24509 | M14: -0.11049616
A15: FY20 | B15: 12 | C15: 51057996 | D15: 4254833 | E15: 4206715 | F15: -1436659 | G15: -0.02736772 | H15: 17838000000 | I15: 1708000000 | J15: 0.10588965 | K15: 4192.409 | L15: 505.17642 | M15: 0.13700693
A16: FY19 | B16: 12 | C16: 52494655 | D16: 4374554.6 | E16: 4352116 | F16: -181772 | G16: -0.0034507276 | H16: 16130000000 | I16: 168000000 | J16: 0.010524997 | K16: 3687.2325 | L16: 50.995024 | M16: 0.014024118
A17: FY18 | B17: 12 | C17: 52676427 | D17: 4389702.2 | E17: 4391939 | F17: -150865 | G17: -0.0028558155 | H17: 15962000000 | I17: 2200000000 | J17: 0.15986049 | K17: 3636.2375 | L17: 510.12611 | M17: 0.16318232
A18: FY17 | B18: 12 | C18: 52827292 | D18: 4402274.3 | E18: 4363641 | F18: -2256316 | G18: -0.04096166 | H18: 13762000000 | I18: 1296000000 | J18: 0.10396278 | K18: 3126.1114 | L18: 410.38516 | M18: 0.15111433
A19: FY16 | B19: 12 | C19: 55083608 | D19: 4590300.7 | E19: 4640405 | F19: 7344942 | G19: 0.15385729 | H19: 12466000000 | I19: -201000000 | J19: -0.015868003 | K19: 2715.7262 | L19: -468.35937 | M19: -0.14709384
A20: FY15 | B20: 12 | C20: 47738666 | D20: 3978222.2 | E20: 4386992 | F20: 5840249 | G20: 0.13939068 | H20: 12667000000 | I20: 1450000000 | J20: 0.12926808 | K20: 3184.0856 | L20: -28.54172 | M20: -0.0088842298
A21: FY14 | B21: 12 | C21: 41898417 | D21: 3491534.8 | E21: 3488599 | F21: -59301 | G21: -0.0014133514 | H21: 11217000000 | I21: 1420000000 | J21: 0.14494233 | K21: 3212.6273 | L21: 410.66371 | M21: 0.14656283
A22: FY13 | B22: 12 | C22: 41957718 | D22: 3496476.5 | E22: 3522128 | F22: 202009 | G22: 0.0048378774 | H22: 9797000000 | I22: 5745531000 | J22: 1.4181352 | K22: 2801.9636 | L22: 1637.6288 | M22: 1.4064929
A23: FY12 | B23: 12 | C23: 41755709 | D23: 3479642.4 | E23: 3522128 | F23: NA | G23: NA | H23: 4051469000 | I23: NA | J23: NA | K23: 1164.3349 | L23: NA | M23: NA
A25: Notes | G25: FY27-FY30 Growth Assumptions
A26: (1) Data sources: Full-year Enrollment 2025 Estimate Represents YTD annualized | G26: You can forecast projected enrollment and State spending by changing the two inputs below:
A27: =_xlfn.CONCAT("(2) Full-year Enrollment 2026 Estimate Represents YTD annualized. Months in YTD = ",B9,".") -> (2) Full-year Enrollment 2026 Estimate Represents YTD annualized. Months in YTD = 11. | G27: Average Annual Enrollment:
A28: =_xlfn.CONCAT("(3) FY26 full-year spending estimate is based an assumption of per capita spending growth = ",ROUND(G30*100,2),"%") -> (3) FY26 full-year spending estimate is based an assumption of per capita spending growth = 1.43% | G28: 0.0181
G29: Average Annual Per Capita Spending:
G30: 0.0143
A32: Definitions
A33: State Fiscal Year: April through March
A34: Enrollee Months: The total number of Medicaid enrollee months reported within the fiscal year.
A35: Average Annual Enrollment: The average number of enrollees per month over the fiscal year, calculated as total enrollee months divided by the number of months reported.
A36: End of Period Enrollment: The total number of Medicaid enrollees at the end of the reporting period. For completed fiscal years, this represents the enrollment total on the final day of the year. For partial fiscal years, it reflects the year-to-date (YTD) enrollment total as of the most recent reporting date.
A37: Enrollee Months Annual Change: The difference in the total number of enrollee months between the current fiscal year and the prior fiscal year.
A38: Enrollee Months % Growth: The percentage increase or decrease in the total enrollee months compared to the prior fiscal year.
A39: State Spending (Millions): The total Medicaid managed care expenditures by the State government, expressed in millions of dollars.
A40: State Spending Annual Change (Millions): The year-over-year change in State spending on Medicaid managed care, expressed in millions of dollars.
A41: State Spending Annual Change %: The percentage change in the State’s share of Medicaid spending compared to the prior fiscal year.
A42: Average Annual Spending per Enrollee: The average amount of State Medicaid spending per enrollee for the fiscal year.
...

Sheet Graph
P2: Actuals
P3: Average Annual Growth Rates (as of FY24)
P5: Average Annual Enrollment
P6: 1 Year | Q6: =AVERAGE(projection_data!E15) -> -0.13942847
P7: 3 Year | Q7: =AVERAGE(projection_data!E13:E15) -> -0.040463368
P8: 5 Year | Q8: =AVERAGE(projection_data!E11:E15) -> 0.018145802
P10: Per Capita Spending State Spending
P11: 1 Year | Q11: =AVERAGE(projection_data!G15) -> 0.06969255
P12: 3 Year | Q12: =AVERAGE(projection_data!G13:G15) -> 0.056740073
P13: 5 Year | Q13: =AVERAGE(projection_data!G11:G15) -> 0.014253216
P15: Projections
P16: Average Annual Growth Rates
P17: You can forecast projected enrollment and State spending by changing the two inputs below:
P19: Average Annual Enrollment | R19: Per Capita State Spending
P20: 0.0181 | R20: 0.0143
P22: Calculations
P23: State Fiscal Year | Q23: Average Annual Enrollment | R23: Per Capita Spending | S23: State Spending
P24: {=projection_data!B16:B20} -> FY26 | Q24: {=projection_data!D16:D20} -> 4637085.7 | R24: {=projection_data!F16:F20} -> 4512.7047 | S24: {=projection_data!C16:C20} -> 2.0925799e+10
P25: FY27 | Q25: 4721016.9 | R25: 4577.2364 | S25: 2.1609211e+10
P26: FY28 | Q26: 4806467.3 | R26: 4642.6909 | S26: 2.2314942e+10
P27: FY29 | Q27: 4893464.4 | R27: 4709.0814 | S27: 2.3043722e+10
P28: FY30 | Q28: 4982036.1 | R28: 4776.4212 | S28: 2.3796303e+10

Sheet projection_data
A1: Data Type | B1: Fiscal Year | C1: State Spending | D1: Average Annual Enrollment | E1: Average Annual Enrollment Change % | F1: Average Annual Spending per Enrollee | G1: Average Annual Spending per Enrollee Annual Change %
A2: Actual | B2: FY12 | C2: 4051469000 | D2: 3479642.4 | E2: NA | F2: 1164.3349 | G2: NA
A3: Actual | B3: FY13 | C3: 9797000000 | D3: 3496476.5 | E3: 0.0048378774 | F3: 2801.9636 | G3: 1.4064929
A4: Actual | B4: FY14 | C4: 11217000000 | D4: 3491534.8 | E4: -0.0014133514 | F4: 3212.6273 | G4: 0.14656283
A5: Actual | B5: FY15 | C5: 12667000000 | D5: 3978222.2 | E5: 0.13939068 | F5: 3184.0856 | G5: -0.0088842298
A6: Actual | B6: FY16 | C6: 12466000000 | D6: 4590300.7 | E6: 0.15385729 | F6: 2715.7262 | G6: -0.14709384
A7: Actual | B7: FY17 | C7: 13762000000 | D7: 4402274.3 | E7: -0.04096166 | F7: 3126.1114 | G7: 0.15111433
A8: Actual | B8: FY18 | C8: 15962000000 | D8: 4389702.2 | E8: -0.0028558155 | F8: 3636.2375 | G8: 0.16318232
A9: Actual | B9: FY19 | C9: 16130000000 | D9: 4374554.6 | E9: -0.0034507276 | F9: 3687.2325 | G9: 0.014024118
A10: Actual | B10: FY20 | C10: 17838000000 | D10: 4254833 | E10: -0.02736772 | F10: 4192.409 | G10: 0.13700693
A11: Actual | B11: FY21 | C11: 17686000000 | D11: 4742618.1 | E11: 0.11464259 | F11: 3729.1639 | G11: -0.11049616
A12: Actual | B12: FY22 | C12: 19634000000 | D12: 5204912 | E12: 0.097476522 | F12: 3772.2059 | G12: 0.011542018
A13: Actual | B13: FY23 | C13: 21104000000 | D13: 5437762.6 | E13: 0.044736699 | F13: 3881.008 | G13: 0.02884308
A14: Actual | B14: FY24 | C14: 22013000000 | D14: 5292583.4 | E14: -0.026698328 | F14: 4159.2164 | G14: 0.07168459
A15: Actual | B15: FY25 | C15: 20264000000 | D15: 4554646.6 | E15: -0.13942847 | F15: 4449.0828 | G15: 0.06969255
A16: Projected | B16: {=CONCATENATE("FY",RIGHT(INDEX(Table1[],ROWS(Table1[]),2),2)+1)} -> FY26 | C16: =D16*F16 -> 2.0925799e+10 | D16: {=(1+Graph!$P$20)*INDEX(Table1[],ROWS(Table1[]),4)} -> 4637085.7 | F16: {=(1+Graph!$R$20)*INDEX(Table1[],ROWS(Table1[]),6)} -> 4512.7047
A17: Projected | B17: =CONCATENATE("FY",RIGHT(B16,2)+1) -> FY27 | C17: =D17*F17 -> 2.1609211e+10 | D17: =(1+Graph!$P$20)*D16 -> 4721016.9 | F17: =(1+Graph!$R$20)*F16 -> 4577.2364
A18: Projected | B18: =CONCATENATE("FY",RIGHT(B17,2)+1) -> FY28 | C18: =D18*F18 -> 2.2314942e+10 | D18: =(1+Graph!$P$20)*D17 -> 4806467.3 | F18: =(1+Graph!$R$20)*F17 -> 4642.6909
A19: Projected | B19: =CONCATENATE("FY",RIGHT(B18,2)+1) -> FY29 | C19: =D19*F19 -> 2.3043722e+10 | D19: =(1+Graph!$P$20)*D18 -> 4893464.4 | F19: =(1+Graph!$R$20)*F18 -> 4709.0814
A20: Projected | B20: =CONCATENATE("FY",RIGHT(B19,2)+1) -> FY30 | C20: =D20*F20 -> 2.3796303e+10 | D20: =(1+Graph!$P$20)*D19 -> 4982036.1 | F20: =(1+Graph!$R$20)*F19 -> 4776.4212
